Workbook

Sheet отчет
A1: Отчет по выполнению вех
H3: № | I3: Название проекта | J3: D | K3: Выполнение на текущий недельный спринт
B4: Значения | K4: кол-во выполненных вех | M4: кол-во выполненных задач
A5: Названия строк | B5: Количество по полю Задача | C5: Сумма по полю Выполнена | D5: =GETPIVOTDATA("Сумма по полю Выполнена",$A$3,"Теги","страт-п-с-26-09, Операционный директор, Старт вехи Pre")/GETPIVOTDATA("Количество по полю Задача",$A$3,"Теги","страт-п-с-26-09, Операционный директор, Старт вехи Pre") -> 0
A6: Лично сентябрь 2026 | B6: 3 | C6: 0 | D6: =GETPIVOTDATA("Сумма по полю Выполнена",$A$3,"Теги","страт-п-с-26-09, Операционный директор, Старт вехи Pre")/GETPIVOTDATA("Количество по полю Задача",$A$3,"Теги","страт-п-с-26-09, Операционный директор, Старт вехи Pre") -> 0 | K6: план | L6: факт | M6: план | N6: факт
A7: страт-п-с-26-09, Операционный директор, Старт вехи Pre | B7: 1 | C7: 0 | D7: =GETPIVOTDATA("Сумма по полю Выполнена",$A$3,"Теги","страт-п-с-26-09, Операционный директор, Старт вехи Pre")/GETPIVOTDATA("Количество по полю Задача",$A$3,"Теги","страт-п-с-26-09, Операционный директор, Старт вехи Pre") -> 0 | H7: 1 | I7: Лично семинар | J7: 46289 | K7: =SUM(GETPIVOTDATA("Количество по полю Задача",$A$3,"Теги","страт-п-с-26-09, Операционный директор, Старт вехи Pre"),GETPIVOTDATA("Количество по полю Задача",$A$3,"Теги","страт-п-с-26-09, Операционный директор, старт вехи Pro")+GETPIVOTDATA("Количество по полю Задача",$A$3,"Теги","страт-п-с-26-09, Операционный директор, финиш вехи Post")) -> 3 | L7: =SUM(GETPIVOTDATA("Сумма по полю Выполнена",$A$3,"Теги","страт-п-с-26-09, Операционный директор, Старт вехи Pre")+GETPIVOTDATA("Сумма по полю Выполнена",$A$3,"Теги","страт-п-с-26-09, Операционный директор, старт вехи Pro")+GETPIVOTDATA("Сумма по полю Выполнена",$A$3,"Теги","страт-п-с-26-09, Операционный директор, финиш вехи Post")) -> 0 | M7: =GETPIVOTDATA("Количество по полю Задача",$A$3) -> 3 | N7: =GETPIVOTDATA("Сумма по полю Выполнена",$A$3) -> 0
A8: страт-п-с-26-09, Операционный директор, старт вехи Pro | B8: 1 | C8: 0 | H8: 2 | J8: дата 2
A9: страт-п-с-26-09, Операционный директор, финиш вехи Post | B9: 1 | C9: 0 | H9: 3 | J9: дата 3
A10: Общий итог | B10: 3 | C10: 0 | H10: N | I10: Проект N | J10: дата N | K10: x | L10: x | M10: х | N10: Х (Y%)
A12: Отчет по выполнению задач
H13: № | I13: Название проекта | J13: D | K13: Выполнение на текущий недельный спринт
K14: кол-во выполненных вех | M14: кол-во выполненных задач
B15: Значения
A16: Названия строк | B16: Количество по полю Задача | C16: Сумма по полю Выполнена | K16: план | L16: факт | M16: план | N16: факт
A17: Лично сентябрь 2026 | B17: 227 | C17: 0 | D17: =GETPIVOTDATA("Сумма по полю Выполнена",$A$15,"название мероприятия","Лично сентябрь 2026")/GETPIVOTDATA("Количество по полю Задача",$A$15,"название мероприятия","Лично сентябрь 2026") -> 0 | H17: 1 | I17: Здраво | J17: дата 1 | K17: 2 | L17: 2 | M17: 41 | N17: 33 (80%)
A18: координатор | B18: 61 | C18: 0 | D18: =GETPIVOTDATA("Сумма по полю Выполнена",$A$15,"название мероприятия","Лично сентябрь 2026")/GETPIVOTDATA("Количество по полю Задача",$A$15,"название мероприятия","Лично сентябрь 2026") -> 0 | H18: 1.1. | I18: Руководитель Дивизиона | M18: 9 | N18: 9 (100%)
A19: лидген | B19: 21 | C19: 0 | D19: =GETPIVOTDATA("Сумма по полю Выполнена",$A$15,"название мероприятия","Лично сентябрь 2026")/GETPIVOTDATA("Количество по полю Задача",$A$15,"название мероприятия","Лично сентябрь 2026") -> 0 | H19: 1.2. | I19: Продюсер | M19: 12 | N19: 12 (100%)
A20: Операцоинный директор | B20: 3 | C20: 0 | D20: =GETPIVOTDATA("Сумма по полю Выполнена",$A$15,"название мероприятия","Лично сентябрь 2026")/GETPIVOTDATA("Количество по полю Задача",$A$15,"название мероприятия","Лично сентябрь 2026") -> 0 | H20: 1.3. | I20: Координатор | M20: 9 | N20: 9 (100%)
A21: продюсер | B21: 66 | C21: 0 | D21: =GETPIVOTDATA("Сумма по полю Выполнена",$A$15,"название мероприятия","Лично сентябрь 2026")/GETPIVOTDATA("Количество по полю Задача",$A$15,"название мероприятия","Лично сентябрь 2026") -> 0 | H21: 1.4. | I21: Лидген | M21: 8 | N21: 8 (100%)
A22: РГП | B22: 41 | C22: 0 | D22: =GETPIVOTDATA("Сумма по полю Выполнена",$A$15,"название мероприятия","Лично сентябрь 2026")/GETPIVOTDATA("Количество по полю Задача",$A$15,"название мероприятия","Лично сентябрь 2026") -> 0 | H22: 1.5. | I22: Руководитель группы продаж | M22: 3 | N22: 3 (100%)
A23: ШП | B23: 35 | C23: 0 | D23: =GETPIVOTDATA("Сумма по полю Выполнена",$A$15,"название мероприятия","Лично сентябрь 2026")/GETPIVOTDATA("Количество по полю Задача",$A$15,"название мероприятия","Лично сентябрь 2026") -> 0 | H23: 2 | I23: Стратегия | J23: дата 2 | K23: 2 | L23: 1 | M23: 34 | N23: 25 (73%)
A24: Общий итог | B24: 227 | C24: 0 | H24: 2.1. | I24: Руководитель Дивизиона | M24: 9 | N24: 4 (44%)
H25: 2.2. | I25: Продюсер | M25: 8 | N25: 8 (100%)
H26: 2.3. | I26: Координатор | M26: 7 | N26: 7 (100%)
H27: 2.4. | I27: Лидген | M27: 4 | N27: 4 (100%)
H28: 2.5. | I28: Руководитель группы продаж | M28: 3 | N28: 2 (66%)
H29: 3 | I29: Реклама | J29: дата 3 | K29: 2 | L29: 1 | M29: 30 | N29: 15 (50%)
H30: 3.1. | I30: Руководитель Дивизиона | M30: 9 | N30: 6 (66%)
H31: 3.2. | I31: Продюсер | M31: 6 | N31: 3 (50%)
H32: 3.3. | I32: Координатор | M32: 5 | N32: 4 (80%)
H33: 3.4. | I33: Лидген | M33: 7 | N33: 1 (14%)
H34: 3.5. | I34: Руководитель группы продаж | M34: 3 | N34: 1 (33%)
H35: N | I35: Проект N | J35: дата N | K35: x | L35: x | M35: х | N35: Х (Y%)

Sheet Worksheet
A1: ID | B1: Проект | C1: Доска | D1: Колонка | E1: Корневая задача | F1: Родительская задача | G1: Автор | H1: Задача | I1: Дата начала | J1: Дедлайн | K1: Оценка времени | L1: Тип | M1: Приоритет | N1: Выполнена | O1: Дата выполнения | P1: Дата создания | Q1: Просроченные дни | R1: Исполнители | S1: Подписчики | T1: Сделка | U1: Изображение | V1: Приватная | W1: Повторяемая | X1: Описание | Y1: Теги | Z1: Потраченное время | AA1: История | AB1: название мероприятия | AC1: роль и мероприятие | AD1: роль
A2: 903 | B2: ЛИЧНО сентябрь 24.09.2026 | C2: Дивизион Конференции | D2: К работе | G2: Екатерина | H2: 3.61. Оплатить оборудование и доп.питание | I2: 28.09.2026 03:00 | J2: 01.10.2026 | L2: Действие | M2: Низкий | N2: N | P2: 29.04.2026 14:01:16 | S2: Екатерина | V2: N | W2: N | Y2: POST, координатор, страт-п-с-26-09 | AA2: 2026-04-29 14:01:17: Екатерина создал(-а) задачу; 2026-04-29 15:01:30: Екатерина изменил(-а) дату на 28.09.2026; 2026-04-29 15:01:32: Екатерина изменил(-а) дату на 28.09.2026 - 28.09.2026; 2026-04-29 15:01:33: Екатерина изменил(-а) дату на 28.09.2026 - 01.10.2026; 2026-04-29 15:01:45: Екатерина добавил(-а) тег POST; 2026-04-29 15:01:47: Екатерина добавил(-а) тег страт-п-с-26-09; 2026-04-29 15:01:50: Екатерина добавил(-а) тег Лидген; 2026-04-29 15:56:05: Екатерина изменил(-а) название на 3.62. Оплатить оборудование и доп.питание; 2026-04-30 10:43:39: Екатерина изменил(-а) название на 3.61. Оплатить оборудование и доп.питание; 2026-04-30 14:43:14: Екатерина убрал(-а) тег страт-п-с-26-09; 2026-04-30 14:43:17: Екатерина убрал(-а) тег Лидген; 2026-04-30 14:43:23: Екатерина добавил(-а) тег координатор; 2026-04-30 14:43:24: Екатерина добавил(-а) тег страт-п-с-26-09 | AB2: Лично сентябрь 2026 | AC2: =VLOOKUP(Y2,'впр данные'!A:B,2,1) -> координатор, страт-п-с-26-09 | AD2: =VLOOKUP(Y2,'впр данные'!A:C,3,1) -> координатор
A3: 459 | B3: ЛИЧНО сентябрь 24.09.2026 | C3: Дивизион Конференции | D3: К работе | G3: Екатерина | H3: 4.05. Проанализировать полученные от продюсеров результаты глубинного исследования | I3: 01.06.2026 03:00 | J3: 04.06.2026 | L3: Действие | M3: Низкий | N3: N | P3: 28.04.2026 18:39:45 | S3: Екатерина | V3: N | W3: N | Y3: PRE, Лидген, страт-п-с-26-09 | AA3: 2026-04-28 18:39:45: Екатерина создал(-а) задачу; 2026-04-29 11:31:52: Екатерина изменил(-а) дату на 02.06.2026; 2026-04-29 11:31:53: Екатерина изменил(-а) дату на 01.06.2026 - 02.06.2026; 2026-04-29 11:31:56: Екатерина изменил(-а) дату на 01.06.2026 - 04.06.2026; 2026-04-29 13:23:39: Екатерина добавил(-а) тег PRE; 2026-04-29 13:23:42: Екатерина добавил(-а) тег лидген; 2026-04-29 13:23:43: Екатерина добавил(-а) тег страт-п-с-26-09; 2026-04-29 13:24:54: Екатерина убрал(-а) тег лидген; 2026-04-29 13:25:03: Екатерина добавил(-а) тег Лидген; 2026-04-30 14:42:56: Екатерина убрал(-а) тег страт-п-с-26-09; 2026-04-30 14:42:59: Екатерина добавил(-а) тег страт-п-с-26-09 | AB3: Лично сентябрь 2026 | AC3: =VLOOKUP(Y3,'впр данные'!A:B,2,1) -> лидген, страт-п-с-26-09 | AD3: =VLOOKUP(Y3,'впр данные'!A:C,3,1) -> лидген
A4: 456 | E4: 4.06. Получить от продюсеров и проанализировать Концепцию и Программу | F4: 4.06. Получить от продюсеров и проанализировать Концепцию и Программу | G4: Екатерина | H4: 4.06.1. Получить от продюсеров и проанализировать Концепцию и Программу | L4: Действие | M4: Низкий | N4: N | P4: 28.04.2026 18:22:41 | S4: Екатерина | V4: N | W4: N | AA4: 2026-04-28 18:22:41: Екатерина создал(-а) задачу | AB4: Лично сентябрь 2026 | AC4: =VLOOKUP(Y4,'впр данные'!A:B,2,1) -> #N/A | AD4: =VLOOKUP(Y4,'впр данные'!A:C,3,1) -> #N/A
A5: 454 | E5: 4.03. Подготовить семантическое ядро | F5: 4.03. Подготовить семантическое ядро | G5: Екатерина | H5: 4.03.1. Для проведение маркетингового анализа и разработки семантического ядра изучить полученные от продюсеров результаты кабинетного исследования | L5: Действие | M5: Низкий | N5: N | P5: 28.04.2026 18:18:38 | S5: Екатерина | V5: N | W5: N | AA5: 2026-04-28 18:18:38: Екатерина создал(-а) задачу; 2026-04-28 19:08:26: Екатерина изменил(-а) название на 4/Для проведение маркетингового анализа и разработки семантического ядра изучить полученные от продюсеров результаты кабинетного исследования; 2026-04-28 19:08:28: Екатерина изменил(-а) название на 4.03Для проведение маркетингового анализа и разработки семантического ядра изучить полученные от продюсеров результаты кабинетного исследования; 2026-04-28 19:08:29: Екатерина изменил(-а) название на 4.03.Для проведение маркетингового анализа и разработки семантического ядра изучить полученные от продюсеров результаты кабинетного исследования; 2026-04-28 19:08:30: Екатерина изменил(-а) название на 4.03.1.Для проведение маркетингового анализа и разработки семантического ядра изучить полученные от продюсеров результаты кабинетного исследования; 2026-04-28 19:08:33: Екатерина изменил(-а) название на 4.03.1. Для проведение маркетингового анализа и разработки семантического ядра изучить полученные от продюсеров результаты кабинетного исследования | AB5: Лично сентябрь 2026 | AC5: =VLOOKUP(Y5,'впр данные'!A:B,2,1) -> #N/A | AD5: =VLOOKUP(Y5,'впр данные'!A:C,3,1) -> #N/A
A6: 453 | E6: 4.01. Подготовиться к Первичному совещанию | F6: 4.01. Подготовиться к Первичному совещанию | G6: Екатерина | H6: 4.01.3. Подготовить базу на основе анализа емкости рынка | L6: Действие | M6: Низкий | N6: N | P6: 28.04.2026 18:12:33 | S6: Екатерина | V6: N | W6: N | AA6: 2026-04-28 18:12:33: Екатерина создал(-а) задачу | AB6: Лично сентябрь 2026 | AC6: =VLOOKUP(Y6,'впр данные'!A:B,2,1) -> #N/A | AD6: =VLOOKUP(Y6,'впр данные'!A:C,3,1) -> #N/A
A7: 452 | E7: 4.01. Подготовиться к Первичному совещанию | F7: 4.01. Подготовиться к Первичному совещанию | G7: Екатерина | H7: 4.01.2. Посчитать емкость рынка | L7: Действие | M7: Низкий | N7: N | P7: 28.04.2026 18:12:14 | S7: Екатерина | V7: N | W7: N | AA7: 2026-04-28 18:12:15: Екатерина создал(-а) задачу | AB7: Лично сентябрь 2026 | AC7: =VLOOKUP(Y7,'впр данные'!A:B,2,1) -> #N/A | AD7: =VLOOKUP(Y7,'впр данные'!A:C,3,1) -> #N/A
A8: 451 | E8: 4.01. Подготовиться к Первичному совещанию | F8: 4.01. Подготовиться к Первичному совещанию | G8: Екатерина | H8: 4.01.1. Презентовать анализ рекламной кампании прошлого мероприятия с декомпозицией каналов | L8: Действие | M8: Низкий | N8: N | P8: 28.04.2026 18:10:33 | S8: Екатерина | V8: N | W8: N | AA8: 2026-04-28 18:10:34: Екатерина создал(-а) задачу; 2026-04-28 18:11:05: Екатерина изменил(-а) название на 4.01.1. Презентовать анализ рекламной кампании прошлого мероприятия с декомпозицией каналов; 2026-04-29 13:22:52: Екатерина добавил(-а) тег PRE; 2026-04-29 13:22:56: Екатерина добавил(-а) тег лидген; 2026-04-29 13:22:58: Екатерина добавил(-а) тег страт-п-с-26-09; 2026-04-29 13:23:10: Екатерина убрал(-а) тег PRE; 2026-04-29 13:23:11: Екатерина убрал(-а) тег лидген; 2026-04-29 13:23:13: Екатерина убрал(-а) тег страт-п-с-26-09 | AB8: Лично сентябрь 2026 | AC8: =VLOOKUP(Y8,'впр данные'!A:B,2,1) -> #N/A | AD8: =VLOOKUP(Y8,'впр данные'!A:C,3,1) -> #N/A
A9: 428 | B9: ЛИЧНО сентябрь 24.09.2026 | C9: Дивизион Конференции | D9: К работе | G9: Екатерина | H9: 4.01. Подготовиться к Первичному совещанию | I9: 18.05.2026 03:00 | J9: 19.05.2026 | L9: Действие | M9: Низкий | N9: N | P9: 28.04.2026 17:29:49 | S9: Екатерина | V9: N | W9: N | Y9: PRE, Лидген, страт-п-с-26-09 | AA9: 2026-04-28 17:29:49: Екатерина скопировал(-а) задачу #212 4.1. Для подготовки к Первичному совещанию Лидгеном презентовать анализ рекламной кампании прошлого мероприятия с декомпозицией каналов и посчитать емкость рынка - на основе нее подготовить базу, а по ней составить план по лидам; 2026-04-28 17:35:18: Екатерина изменил(-а) название на 4.01. Для подготовки к Первичному совещанию Лидгеном презентовать анализ рекламной кампании прошлого мероприятия с декомпозицией каналов и посчитать емкость рынка - на основе нее подготовить базу, а по ней составить план по лидам - Копия; 2026-04-28 18:10:34: Екатерина добавил(-а) подзадачу #451 4.01.1. Презентовать анализ рекламной кампании прошлого мероприятия с декомпозицией каналов; 2026-04-28 18:12:15: Екатерина добавил(-а) подзадачу #452 4.01.2. Посчитать емкость рынка; 2026-04-28 18:12:34: Екатерина добавил(-а) подзадачу #453 4.01.3. Подготовить базу на основе анализа емкости рынка; 2026-04-28 18:13:11: Екатерина изменил(-а) название на 4.01. Подготовиться к; 2026-04-28 18:13:16: Екатерина изменил(-а) название на 4.01. Подготовиться к Первичному совещанию; 2026-04-29 10:00:22: Екатерина добавил(-а) тег лидген; 2026-04-29 11:30:19: Екатерина изменил(-а) дату на 10.05.2026 - 06.07.2026; 2026-04-29 11:30:20: Екатерина изменил(-а) дату на 10.05.2026 - 11.05.2026; 2026-04-29 11:30:30: Екатерина изменил(-а) дату на 10.05.2026 - 19.05.2026; 2026-04-29 11:30:34: Екатерина изменил(-а) дату на 18.05.2026 - 19.05.2026; 2026-04-29 13:22:48: Екатерина добавил(-а) тег PRE; 2026-04-29 13:23:02: Екатерина добавил(-а) тег страт-п-с-26-09; 2026-04-30 14:37:49: Екатерина убрал(-а) тег лидген; 2026-04-30 14:37:51: Екатерина убрал(-а) тег страт-п-с-26-09; 2026-04-30 14:37:58: Екатерина добавил(-а) тег лидген; 2026-04-30 14:38:02: Екатерина добавил(-а) тег страт-п-с-26-09; 2026-04-30 14:43:35: Екатерина убрал(-а) тег лидген; 2026-04-30 14:43:37: Екатерина убрал(-а) тег страт-п-с-26-09; 2026-04-30 14:43:41: Екатерина добавил(-а) тег Лидген; 2026-04-30 14:43:43: Екатерина добавил(-а) тег страт-п-с-26-09 | AB9: Лично сентябрь 2026 | AC9: =VLOOKUP(Y9,'впр данные'!A:B,2,1) -> лидген, страт-п-с-26-09 | AD9: =VLOOKUP(Y9,'впр данные'!A:C,3,1) -> лидген
A10: 427 | B10: ЛИЧНО сентябрь 24.09.2026 | C10: Дивизион Конференции | D10: К работе | G10: Екатерина | H10: 3.60. Проведено итоговое совещание по проекту | I10: 28.09.2026 03:00 | J10: 01.10.2026 | L10: Действие | M10: Низкий | N10: N | P10: 28.04.2026 17:00:20 | S10: Екатерина | V10: N | W10: N | Y10: POST, координатор, страт-п-с-26-09 | AA10: 2026-04-28 17:00:20: Екатерина создал(-а) задачу; 2026-04-29 11:28:33: Екатерина изменил(-а) дату на 29.09.2026; 2026-04-29 11:28:34: Екатерина изменил(-а) дату на 28.09.2026 - 29.09.2026; 2026-04-29 11:28:37: Екатерина изменил(-а) дату на 28.09.2026 - 01.10.2026; 2026-04-29 13:22:18: Екатерина добавил(-а) тег POST; 2026-04-29 13:22:40: Екатерина добавил(-а) тег координатор; 2026-04-29 13:22:41: Екатерина добавил(-а) тег страт-п-с-26-09; 2026-04-29 15:56:02: Екатерина изменил(-а) название на 3.61. Проведено итоговое совещание по проекту; 2026-04-30 10:43:36: Екатерина изменил(-а) название на 3.60. Проведено итоговое совещание по проекту | AB10: Лично сентябрь 2026 | AC10: =VLOOKUP(Y10,'впр данные'!A:B,2,1) -> координатор, страт-п-с-26-09 | AD10: =VLOOKUP(Y10,'впр данные'!A:C,3,1) -> координатор
A11: 426 | B11: ЛИЧНО сентябрь 24.09.2026 | C11: Дивизион Конференции | D11: К работе | G11: Екатерина | H11: 3.59. Отправлены благодарности, презентации, фотографии участникам | I11: 28.09.2026 03:00 | J11: 01.10.2026 | L11: Действие | M11: Низкий | N11: N | P11: 28.04.2026 16:59:49 | S11: Екатерина | V11: N | W11: N | Y11: POST, координатор, страт-п-с-26-09 | AA11: 2026-04-28 16:59:49: Екатерина создал(-а) задачу; 2026-04-29 11:28:49: Екатерина изменил(-а) дату на 29.09.2026; 2026-04-29 11:28:50: Екатерина изменил(-а) дату на 27.09.2026 - 29.09.2026; 2026-04-29 11:28:52: Екатерина изменил(-а) дату на 27.09.2026 - 02.10.2026; 2026-04-29 11:28:53: Екатерина изменил(-а) дату на 28.09.2026 - 02.10.2026; 2026-04-29 11:28:55: Екатерина изменил(-а) дату на 28.09.2026 - 01.10.2026; 2026-04-29 13:22:14: Екатерина добавил(-а) тег POST; 2026-04-29 13:22:28: Екатерина добавил(-а) тег координатор; 2026-04-29 13:22:29: Екатерина добавил(-а) тег страт-п-с-26-09; 2026-04-29 15:55:58: Екатерина изменил(-а) название на 3.60. Отправлены благодарности, презентации, фотографии участникам; 2026-04-30 10:43:31: Екатерина изменил(-а) название на 3.59. Отправлены благодарности, презентации, фотографии участникам | AB11: Лично сентябрь 2026 | AC11: =VLOOKUP(Y11,'впр данные'!A:B,2,1) -> координатор, страт-п-с-26-09 | AD11: =VLOOKUP(Y11,'впр данные'!A:C,3,1) -> координатор
A12: 425 | B12: ЛИЧНО сентябрь 24.09.2026 | C12: Дивизион Конференции | D12: К работе | G12: Екатерина | H12: 3.58. Подготовлен отчет + и - мероприятия | I12: 28.09.2026 03:00 | J12: 01.10.2026 | L12: Действие | M12: Низкий | N12: N | P12: 28.04.2026 16:59:37 | S12: Екатерина | V12: N | W12: N | Y12: POST, координатор, страт-п-с-26-09 | AA12: 2026-04-28 16:59:37: Екатерина создал(-а) задачу; 2026-04-28 17:00:05: Екатерина изменил(-а) название на 3.62. Подготовлен отчет + и +- мероприятия; 2026-04-28 17:00:07: Екатерина изменил(-а) название на 3.62. Подготовлен отчет + и - мероприятия; 2026-04-29 11:28:39: Екатерина изменил(-а) дату на 29.09.2026; 2026-04-29 11:28:41: Екатерина изменил(-а) дату на 27.09.2026 - 29.09.2026; 2026-04-29 11:28:43: Екатерина изменил(-а) дату на 27.09.2026 - 02.10.2026; 2026-04-29 11:28:46: Екатерина изменил(-а) дату на 28.09.2026 - 02.10.2026; 2026-04-29 11:28:49: Екатерина изменил(-а) дату на 28.09.2026 - 01.10.2026; 2026-04-29 13:22:10: Екатерина добавил(-а) тег POST; 2026-04-29 13:22:22: Екатерина добавил(-а) тег координатор; 2026-04-29 13:22:23: Екатерина добавил(-а) тег страт-п-с-26-09; 2026-04-29 15:55:51: Екатерина изменил(-а) название на 3.59. Подготовлен отчет + и - мероприятия; 2026-04-30 10:43:26: Екатерина изменил(-а) название на 3.58. Подготовлен отчет + и - мероприятия | AB12: Лично сентябрь 2026 | AC12: =VLOOKUP(Y12,'впр данные'!A:B,2,1) -> координатор, страт-п-с-26-09 | AD12: =VLOOKUP(Y12,'впр данные'!A:C,3,1) -> координатор
A13: 424 | B13: ЛИЧНО сентябрь 24.09.2026 | C13: Дивизион Конференции | D13: К работе | G13: Екатерина | H13: 3.57. Подготовлен отчет по подотчетным | I13: 28.09.2026 03:00 | J13: 01.10.2026 | L13: Действие | M13: Низкий | N13: N | P13: 28.04.2026 16:59:26 | S13: Екатерина | V13: N | W13: N | Y13: POST, координатор, страт-п-с-26-09 | AA13: 2026-04-28 16:59:26: Екатерина создал(-а) задачу; 2026-04-29 11:11:02: Екатерина добавил(-а) тег POST; 2026-04-29 11:28:15: Екатерина изменил(-а) дату на 26.09.2026; 2026-04-29 11:28:18: Екатерина изменил(-а) дату на 26.09.2026 - 29.09.2026; 2026-04-29 11:28:22: Екатерина изменил(-а) дату на 28.09.2026 - 29.09.2026; 2026-04-29 11:28:26: Екатерина изменил(-а) дату на 28.09.2026 - 01.10.2026; 2026-04-29 13:22:04: Екатерина добавил(-а) тег координатор; 2026-04-29 13:22:06: Екатерина добавил(-а) тег страт-п-с-26-09; 2026-04-29 15:55:46: Екатерина изменил(-а) название на 3.58. Подготовлен отчет по подотчетным; 2026-04-30 10:43:22: Екатерина изменил(-а) название на 3.57. Подготовлен отчет по подотчетным | AB13: Лично сентябрь 2026 | AC13: =VLOOKUP(Y13,'впр данные'!A:B,2,1) -> координатор, страт-п-с-26-09 | AD13: =VLOOKUP(Y13,'впр данные'!A:C,3,1) -> координатор
A14: 423 | B14: ЛИЧНО сентябрь 24.09.2026 | C14: Дивизион Конференции | D14: К работе | G14: Екатерина | H14: 3.56. Сверка на предмет участие, все ли оплатившие пришли, чтобы исключить претензии | J14: 24.09.2026 | L14: Действие | M14: Низкий | N14: N | P14: 28.04.2026 16:59:17 | S14: Екатерина | V14: N | W14: N | Y14: D, координатор, страт-п-с-26-09 | AA14: 2026-04-28 16:59:17: Екатерина создал(-а) задачу; 2026-04-29 11:28:08: Екатерина изменил(-а) дату на 24.09.2026; 2026-04-29 11:28:09: Екатерина изменил(-а) дату на 24.09.2026 - 25.09.2026; 2026-04-29 11:28:13: Екатерина изменил(-а) дату на 24.09.2026; 2026-04-29 13:21:34: Екатерина добавил(-а) тег D; 2026-04-29 13:21:58: Екатерина добавил(-а) тег координатор; 2026-04-29 13:21:59: Екатерина добавил(-а) тег страт-п-с-26-09; 2026-04-29 15:55:10: Екатерина изменил(-а) название на 3.57. Сверка на предмет участие, все ли оплатившие пришли, чтобы исключить претензии; 2026-04-30 10:43:17: Екатерина изменил(-а) название на 3.55. Сверка на предмет участие, все ли оплатившие пришли, чтобы исключить претензии; 2026-04-30 10:43:17: Екатерина изменил(-а) название на 3.5. Сверка на предмет участие, все ли оплатившие пришли, чтобы исключить претензии; 2026-04-30 10:43:18: Екатерина изменил(-а) название на 3.56. Сверка на предмет участие, все ли оплатившие пришли, чтобы исключить претензии | AB14: Лично сентябрь 2026 | AC14: =VLOOKUP(Y14,'впр данные'!A:B,2,1) -> координатор, страт-п-с-26-09 | AD14: =VLOOKUP(Y14,'впр данные'!A:C,3,1) -> координатор
A15: 422 | B15: ЛИЧНО сентябрь 24.09.2026 | C15: Дивизион Конференции | D15: К работе | G15: Екатерина | H15: 3.55. День мероприятия: Меропритиятие проведено | J15: 24.09.2026 | L15: Действие | M15: Низкий | N15: N | P15: 28.04.2026 16:59:03 | S15: Екатерина | V15: N | W15: N | Y15: D, координатор, страт-п-с-26-09 | AA15: 2026-04-28 16:59:03: Екатерина создал(-а) задачу; 2026-04-29 11:27:51: Екатерина изменил(-а) дату на 25.09.2026; 2026-04-29 11:27:54: Екатерина изменил(-а) дату на 24.09.2026 - 25.09.2026; 2026-04-29 11:27:56: Екатерина изменил(-а) дату на 24.09.2026; 2026-04-29 13:21:32: Екатерина добавил(-а) тег D; 2026-04-29 13:21:52: Екатерина добавил(-а) тег координатор; 2026-04-29 13:21:54: Екатерина добавил(-а) тег страт-п-с-26-09; 2026-04-29 15:53:22: Екатерина изменил(-а) название на 3.56. День мероприятия: Меропритиятие проведено; 2026-04-30 10:43:10: Екатерина изменил(-а) название на 3.55. День мероприятия: Меропритиятие проведено | AB15: Лично сентябрь 2026 | AC15: =VLOOKUP(Y15,'впр данные'!A:B,2,1) -> координатор, страт-п-с-26-09 | AD15: =VLOOKUP(Y15,'впр данные'!A:C,3,1) -> координатор
A16: 421 | B16: ЛИЧНО сентябрь 24.09.2026 | C16: Дивизион Конференции | D16: К работе | G16: Екатерина | H16: 3.54. День монтажа: площадка подготовлена: заезд, накрытие зала, накрытие регистрации, заезд и контроль подрядчиков: питание, оборудование, полиграфия и т.д. | J16: 23.09.2026 | L16: Действие | M16: Низкий | N16: N | P16: 28.04.2026 16:58:51 | S16: Екатерина | V16: N | W16: N | Y16: D, координатор, страт-п-с-26-09 | AA16: 2026-04-28 16:58:51: Екатерина создал(-а) задачу; 2026-04-29 11:10:53: Екатерина добавил(-а) тег D; 2026-04-29 11:27:41: Екатерина изменил(-а) дату на 20.09.2026; 2026-04-29 11:27:44: Екатерина изменил(-а) дату на 20.09.2026 - 23.09.2026; 2026-04-29 11:27:49: Екатерина изменил(-а) дату на 23.09.2026; 2026-04-29 13:21:44: Екатерина добавил(-а) тег координатор; 2026-04-29 13:21:46: Екатерина добавил(-а) тег страт-п-с-26-09; 2026-04-29 15:53:17: Екатерина изменил(-а) название на 3.55. День монтажа: площадка подготовлена: заезд, накрытие зала, накрытие регистрации, заезд и контроль подрядчиков: питание, оборудование, полиграфия и т.д.; 2026-04-30 10:43:06: Екатерина изменил(-а) название на 3.54. День монтажа: площадка подготовлена: заезд, накрытие зала, накрытие регистрации, заезд и контроль подрядчиков: питание, оборудование, полиграфия и т.д. | AB16: Лично сентябрь 2026 | AC16: =VLOOKUP(Y16,'впр данные'!A:B,2,1) -> координатор, страт-п-с-26-09 | AD16: =VLOOKUP(Y16,'впр данные'!A:C,3,1) -> координатор
A17: 420 | B17: ЛИЧНО сентябрь 24.09.2026 | C17: Дивизион Конференции | D17: К работе | G17: Екатерина | H17: 3.53. Произведена проверка битрикса-списка участников с бухреестром | I17: 14.09.2026 03:00 | J17: 17.09.2026 | L17: Действие | M17: Низкий | N17: N | P17: 28.04.2026 16:58:37 | S17: Екатерина | V17: N | W17: N | Y17: PRO, координатор, страт-п-с-26-09 | AA17: 2026-04-28 16:58:37: Екатерина создал(-а) задачу; 2026-04-29 11:26:30: Екатерина изменил(-а) дату на 14.09.2026; 2026-04-29 11:26:31: Екатерина изменил(-а) дату на 13.09.2026 - 14.09.2026; 2026-04-29 11:26:36: Екатерина изменил(-а) дату на 13.09.2026 - 16.09.2026; 2026-04-29 11:26:39: Екатерина изменил(-а) дату на 14.09.2026 - 16.09.2026; 2026-04-29 11:26:41: Екатерина изменил(-а) дату на 14.09.2026 - 17.09.2026; 2026-04-29 13:21:21: Екатерина добавил(-а) тег PRO; 2026-04-29 13:21:23: Екатерина добавил(-а) тег координатор; 2026-04-29 13:21:25: Екатерина добавил(-а) тег страт-п-с-26-09; 2026-04-29 15:53:09: Екатерина изменил(-а) название на 3.54. Произведена проверка битрикса-списка участников с бухреестром; 2026-04-30 10:43:00: Екатерина изменил(-а) название на 3.53. Произведена проверка битрикса-списка участников с бухреестром | AB17: Лично сентябрь 2026 | AC17: =VLOOKUP(Y17,'впр данные'!A:B,2,1) -> координатор, страт-п-с-26-09 | AD17: =VLOOKUP(Y17,'впр данные'!A:C,3,1) -> координатор
A18: 419 | B18: ЛИЧНО сентябрь 24.09.2026 | C18: Дивизион Конференции | D18: К работе | G18: Екатерина | H18: 3.52. Куплены подарки спикерам при необходимости | I18: 14.09.2026 03:00 | J18: 17.09.2026 | L18: Действие | M18: Низкий | N18: N | P18: 28.04.2026 16:58:26 | S18: Екатерина | V18: N | W18: N | Y18: PRO, координатор, страт-п-с-26-09 | AA18: 2026-04-28 16:58:27: Екатерина создал(-а) задачу; 2026-04-29 11:27:27: Екатерина изменил(-а) дату на 15.09.2026; 2026-04-29 11:27:29: Екатерина изменил(-а) дату на 14.09.2026 - 15.09.2026; 2026-04-29 11:27:32: Екатерина изменил(-а) дату на 14.09.2026 - 17.09.2026; 2026-04-29 13:21:14: Екатерина добавил(-а) тег PRO; 2026-04-29 13:21:17: Екатерина добавил(-а) тег координатор; 2026-04-29 13:21:18: Екатерина добавил(-а) тег страт-п-с-26-09; 2026-04-29 15:16:38: Екатерина изменил(-а) название на 3.53. Куплены подарки спикерам при необходимости; 2026-04-30 10:42:56: Екатерина изменил(-а) название на 3.52. Куплены подарки спикерам при необходимости | AB18: Лично сентябрь 2026 | AC18: =VLOOKUP(Y18,'впр данные'!A:B,2,1) -> координатор, страт-п-с-26-09 | AD18: =VLOOKUP(Y18,'впр данные'!A:C,3,1) -> координатор
A19: 418 | B19: ЛИЧНО сентябрь 24.09.2026 | C19: Дивизион Конференции | D19: К работе | G19: Екатерина | H19: 3.51. Получены деньги подотчет для мероприятия | I19: 14.09.2026 03:00 | J19: 17.09.2026 | L19: Действие | M19: Низкий | N19: N | P19: 28.04.2026 16:58:14 | S19: Екатерина | V19: N | W19: N | Y19: PRO, координатор, страт-п-с-26-09 | AA19: 2026-04-28 16:58:14: Екатерина создал(-а) задачу; 2026-04-29 11:27:23: Екатерина изменил(-а) дату на 15.09.2026; 2026-04-29 11:27:25: Екатерина изменил(-а) дату на 14.09.2026 - 15.09.2026; 2026-04-29 11:27:26: Екатерина изменил(-а) дату на 14.09.2026 - 17.09.2026; 2026-04-29 13:21:06: Екатерина добавил(-а) тег PRO; 2026-04-29 13:21:09: Екатерина добавил(-а) тег координатор; 2026-04-29 13:21:10: Екатерина добавил(-а) тег страт-п-с-26-09; 2026-04-29 15:16:35: Екатерина изменил(-а) название на 3.52. Получены деньги подотчет для мероприятия; 2026-04-30 10:42:52: Екатерина изменил(-а) название на 3.51. Получены деньги подотчет для мероприятия | AB19: Лично сентябрь 2026 | AC19: =VLOOKUP(Y19,'впр данные'!A:B,2,1) -> координатор, страт-п-с-26-09 | AD19: =VLOOKUP(Y19,'впр данные'!A:C,3,1) -> координатор
A20: 417 | B20: ЛИЧНО сентябрь 24.09.2026 | C20: Дивизион Конференции | D20: К работе | G20: Екатерина | H20: 3.50. На площадку сдана вся информация: рассадка, расстановка, списки, машины, картинки, тайминг и т.д. | I20: 14.09.2026 03:00 | J20: 17.09.2026 | L20: Действие | M20: Низкий | N20: N | P20: 28.04.2026 16:58:02 | S20: Екатерина | V20: N | W20: N | Y20: PRO, координатор, страт-п-с-26-09 | AA20: 2026-04-28 16:58:02: Екатерина создал(-а) задачу; 2026-04-29 11:27:20: Екатерина изменил(-а) дату на 15.09.2026; 2026-04-29 11:27:21: Екатерина изменил(-а) дату на 14.09.2026 - 15.09.2026; 2026-04-29 11:27:22: Екатерина изменил(-а) дату на 14.09.2026 - 17.09.2026; 2026-04-29 13:20:59: Екатерина добавил(-а) тег PRO; 2026-04-29 13:21:03: Екатерина добавил(-а) тег координатор; 2026-04-29 13:21:03: Екатерина добавил(-а) тег страт-п-с-26-09; 2026-04-29 15:16:32: Екатерина изменил(-а) название на 3.51. На площадку сдана вся информация: рассадка, расстановка, списки, машины, картинки, тайминг и т.д.; 2026-04-30 10:42:49: Екатерина изменил(-а) название на 3.50. На площадку сдана вся информация: рассадка, расстановка, списки, машины, картинки, тайминг и т.д. | AB20: Лично сентябрь 2026 | AC20: =VLOOKUP(Y20,'впр данные'!A:B,2,1) -> координатор, страт-п-с-26-09 | AD20: =VLOOKUP(Y20,'впр данные'!A:C,3,1) -> координатор
A21: 416 | B21: ЛИЧНО сентябрь 24.09.2026 | C21: Дивизион Конференции | D21: К работе | G21: Екатерина | H21: 3.49. Получено подтверждение по доставке и заезду | I21: 14.09.2026 03:00 | J21: 17.09.2026 | L21: Действие | M21: Низкий | N21: N | P21: 28.04.2026 16:57:50 | S21: Екатерина | V21: N | W21: N | Y21: PRO, координатор, страт-п-с-26-09 | AA21: 2026-04-28 16:57:51: Екатерина создал(-а) задачу; 2026-04-29 11:27:15: Екатерина изменил(-а) дату на 15.09.2026; 2026-04-29 11:27:16: Екатерина изменил(-а) дату на 14.09.2026 - 15.09.2026; 2026-04-29 11:27:18: Екатерина изменил(-а) дату на 14.09.2026 - 17.09.2026; 2026-04-29 13:20:52: Екатерина добавил(-а) тег PRO; 2026-04-29 13:20:55: Екатерина добавил(-а) тег координатор; 2026-04-29 13:20:56: Екатерина добавил(-а) тег страт-п-с-26-09; 2026-04-29 15:16:24: Екатерина изменил(-а) название на 3.50. Получено подтверждение по доставке и заезду; 2026-04-30 10:42:46: Екатерина изменил(-а) название на 3.49. Получено подтверждение по доставке и заезду | AB21: Лично сентябрь 2026 | AC21: =VLOOKUP(Y21,'впр данные'!A:B,2,1) -> координатор, страт-п-с-26-09 | AD21: =VLOOKUP(Y21,'впр данные'!A:C,3,1) -> координатор
A22: 415 | B22: ЛИЧНО сентябрь 24.09.2026 | C22: Дивизион Конференции | D22: К работе | G22: Екатерина | H22: 3.48. Рабочая тетрадь, оформление сдано в типографию | I22: 14.09.2026 03:00 | J22: 17.09.2026 | L22: Действие | M22: Низкий | N22: N | P22: 28.04.2026 16:57:41 | S22: Екатерина | V22: N | W22: N | Y22: PRO, координатор, страт-п-с-26-09 | AA22: 2026-04-28 16:57:41: Екатерина создал(-а) задачу; 2026-04-29 11:27:08: Екатерина изменил(-а) дату на 15.09.2026; 2026-04-29 11:27:10: Екатерина изменил(-а) дату на 14.09.2026 - 15.09.2026; 2026-04-29 11:27:11: Екатерина изменил(-а) дату на 14.09.2026 - 17.09.2026; 2026-04-29 13:19:58: Екатерина добавил(-а) тег PRO; 2026-04-29 13:20:02: Екатерина добавил(-а) тег координатор; 2026-04-29 13:20:03: Екатерина добавил(-а) тег страт-п-с-26-09; 2026-04-29 15:16:17: Екатерина изменил(-а) название на 3.49. Рабочая тетрадь, оформление сдано в типографию; 2026-04-30 10:42:39: Екатерина изменил(-а) название на 3.48. Рабочая тетрадь, оформление сдано в типографию | AB22: Лично сентябрь 2026 | AC22: =VLOOKUP(Y22,'впр данные'!A:B,2,1) -> координатор, страт-п-с-26-09 | AD22: =VLOOKUP(Y22,'впр данные'!A:C,3,1) -> координатор
A23: 414 | B23: ЛИЧНО сентябрь 24.09.2026 | C23: Дивизион Конференции | D23: К работе | G23: Екатерина | H23: 3.47. Проведена совещание-распределение с рабочей группой, кто едет на меропритие | I23: 14.09.2026 03:00 | J23: 17.09.2026 | L23: Действие | M23: Низкий | N23: N | P23: 28.04.2026 16:57:27 | S23: Екатерина | V23: N | W23: N | Y23: PRO, координатор, страт-п-с-26-09 | AA23: 2026-04-28 16:57:28: Екатерина создал(-а) задачу; 2026-04-29 11:27:04: Екатерина изменил(-а) дату на 15.09.2026; 2026-04-29 11:27:05: Екатерина изменил(-а) дату на 14.09.2026 - 15.09.2026; 2026-04-29 11:27:07: Екатерина изменил(-а) дату на 14.09.2026 - 17.09.2026; 2026-04-29 13:19:50: Екатерина добавил(-а) тег PRO; 2026-04-29 13:19:55: Екатерина добавил(-а) тег координатор; 2026-04-29 13:19:55: Екатерина добавил(-а) тег страт-п-с-26-09; 2026-04-29 15:16:12: Екатерина изменил(-а) название на 3.48. Проведена совещание-распределение с рабочей группой, кто едет на меропритие; 2026-04-30 10:42:36: Екатерина изменил(-а) название на 3.47. Проведена совещание-распределение с рабочей группой, кто едет на меропритие | AB23: Лично сентябрь 2026 | AC23: =VLOOKUP(Y23,'впр данные'!A:B,2,1) -> координатор, страт-п-с-26-09 | AD23: =VLOOKUP(Y23,'впр данные'!A:C,3,1) -> координатор
A24: 413 | B24: ЛИЧНО сентябрь 24.09.2026 | C24: Дивизион Конференции | D24: К работе | G24: Екатерина | H24: 3.46. Сформирована папка координатора | I24: 14.09.2026 03:00 | J24: 17.09.2026 | L24: Действие | M24: Низкий | N24: N | P24: 28.04.2026 16:57:16 | S24: Екатерина | V24: N | W24: N | Y24: PRO, координатор, страт-п-с-26-09 | AA24: 2026-04-28 16:57:16: Екатерина создал(-а) задачу; 2026-04-29 11:26:59: Екатерина изменил(-а) дату на 15.09.2026; 2026-04-29 11:27:01: Екатерина изменил(-а) дату на 14.09.2026 - 15.09.2026; 2026-04-29 11:27:02: Екатерина изменил(-а) дату на 14.09.2026 - 17.09.2026; 2026-04-29 13:19:43: Екатерина добавил(-а) тег PRO; 2026-04-29 13:19:47: Екатерина добавил(-а) тег координатор; 2026-04-29 13:19:47: Екатерина добавил(-а) тег страт-п-с-26-09; 2026-04-29 15:16:08: Екатерина изменил(-а) название на 3.47. Сформирована папка координатора; 2026-04-30 10:42:33: Екатерина изменил(-а) название на 3.46. Сформирована папка координатора | AB24: Лично сентябрь 2026 | AC24: =VLOOKUP(Y24,'впр данные'!A:B,2,1) -> координатор, страт-п-с-26-09 | AD24: =VLOOKUP(Y24,'впр данные'!A:C,3,1) -> координатор
A25: 412 | B25: ЛИЧНО сентябрь 24.09.2026 | C25: Дивизион Конференции | D25: К работе | G25: Екатерина | H25: 3.45. Сформирована папка участников мероприятия: бейджи, бух документы | I25: 14.09.2026 03:00 | J25: 17.09.2026 | L25: Действие | M25: Низкий | N25: N | P25: 28.04.2026 16:57:03 | S25: Екатерина | V25: N | W25: N | Y25: PRO, координатор, страт-п-с-26-09 | AA25: 2026-04-28 16:57:04: Екатерина создал(-а) задачу; 2026-04-29 11:26:53: Екатерина изменил(-а) дату на 15.09.2026; 2026-04-29 11:26:55: Екатерина изменил(-а) дату на 14.09.2026 - 15.09.2026; 2026-04-29 11:26:57: Екатерина изменил(-а) дату на 14.09.2026 - 17.09.2026; 2026-04-29 13:19:36: Екатерина добавил(-а) тег PRO; 2026-04-29 13:19:38: Екатерина добавил(-а) тег координатор; 2026-04-29 13:19:40: Екатерина добавил(-а) тег страт-п-с-26-09; 2026-04-29 15:16:03: Екатерина изменил(-а) название на 3.46. Сформирована папка участников мероприятия: бейджи, бух документы; 2026-04-30 10:42:28: Екатерина изменил(-а) название на 3.45. Сформирована папка участников мероприятия: бейджи, бух документы | AB25: Лично сентябрь 2026 | AC25: =VLOOKUP(Y25,'впр данные'!A:B,2,1) -> координатор, страт-п-с-26-09 | AD25: =VLOOKUP(Y25,'впр данные'!A:C,3,1) -> координатор
A26: 411 | B26: ЛИЧНО сентябрь 24.09.2026 | C26: Дивизион Конференции | D26: К работе | G26: Екатерина | H26: 3.44. Памятки отправлены всем | I26: 14.09.2026 03:00 | J26: 17.09.2026 | L26: Действие | M26: Низкий | N26: N | P26: 28.04.2026 16:56:52 | S26: Екатерина | V26: N | W26: N | Y26: PRO, координатор, страт-п-с-26-09 | AA26: 2026-04-28 16:56:52: Екатерина создал(-а) задачу; 2026-04-29 11:26:49: Екатерина изменил(-а) дату на 15.09.2026; 2026-04-29 11:26:50: Екатерина изменил(-а) дату на 14.09.2026 - 15.09.2026; 2026-04-29 11:26:52: Екатерина изменил(-а) дату на 14.09.2026 - 17.09.2026; 2026-04-29 13:19:29: Екатерина добавил(-а) тег PRO; 2026-04-29 13:19:32: Екатерина добавил(-а) тег координатор; 2026-04-29 13:19:33: Екатерина добавил(-а) тег страт-п-с-26-09; 2026-04-29 15:15:59: Екатерина изменил(-а) название на 3.45. Памятки отправлены всем; 2026-04-30 10:42:24: Екатерина изменил(-а) название на 3.44. Памятки отправлены всем | AB26: Лично сентябрь 2026 | AC26: =VLOOKUP(Y26,'впр данные'!A:B,2,1) -> координатор, страт-п-с-26-09 | AD26: =VLOOKUP(Y26,'впр данные'!A:C,3,1) -> координатор
A27: 410 | B27: ЛИЧНО сентябрь 24.09.2026 | C27: Дивизион Конференции | D27: К работе | G27: Екатерина | H27: 3.43. Сформирован и оплачен окончательный заказ по площадке и подрядчикам, ВСЕМУ | I27: 14.09.2026 03:00 | J27: 17.09.2026 | L27: Действие | M27: Низкий | N27: N | P27: 28.04.2026 16:56:39 | S27: Екатерина | V27: N | W27: N | Y27: PRO, координатор, страт-п-с-26-09 | AA27: 2026-04-28 16:56:40: Екатерина создал(-а) задачу; 2026-04-29 11:26:43: Екатерина изменил(-а) дату на 15.09.2026; 2026-04-29 11:26:46: Екатерина изменил(-а) дату на 15.09.2026 - 17.09.2026; 2026-04-29 11:26:48: Екатерина изменил(-а) дату на 14.09.2026 - 17.09.2026; 2026-04-29 13:19:19: Екатерина добавил(-а) тег PRO; 2026-04-29 13:19:23: Екатерина добавил(-а) тег координатор; 2026-04-29 13:19:25: Екатерина добавил(-а) тег страт-п-с-26-09; 2026-04-29 15:15:56: Екатерина изменил(-а) название на 3.44. Сформирован и оплачен окончательный заказ по площадке и подрядчикам, ВСЕМУ; 2026-04-30 10:42:21: Екатерина изменил(-а) название на 3.43. Сформирован и оплачен окончательный заказ по площадке и подрядчикам, ВСЕМУ | AB27: Лично сентябрь 2026 | AC27: =VLOOKUP(Y27,'впр данные'!A:B,2,1) -> координатор, страт-п-с-26-09 | AD27: =VLOOKUP(Y27,'впр данные'!A:C,3,1) -> координатор
A28: 408 | B28: ЛИЧНО сентябрь 24.09.2026 | C28: Дивизион Конференции | D28: К работе | G28: Екатерина | H28: 3.42. Техническая подготовка завершена | I28: 14.09.2026 03:00 | J28: 17.09.2026 | L28: Действие | M28: Низкий | N28: N | P28: 28.04.2026 16:56:20 | S28: Екатерина | V28: N | W28: N | Y28: PRO, координатор, страт-п-с-26-09 | AA28: 2026-04-28 16:56:20: Екатерина создал(-а) задачу; 2026-04-29 11:25:28: Екатерина изменил(-а) дату на 08.09.2026; 2026-04-29 11:25:37: Екатерина изменил(-а) дату на 08.09.2026 - 19.09.2026; 2026-04-29 11:25:46: Екатерина изменил(-а) дату на 19.09.2026; 2026-04-29 11:25:56: Екатерина изменил(-а) дату на 19.09.2026 - 22.09.2026; 2026-04-29 11:26:12: Екатерина изменил(-а) дату на 14.09.2026 - 22.09.2026; 2026-04-29 11:26:16: Екатерина изменил(-а) дату на 14.09.2026 - 17.09.2026; 2026-04-29 13:19:03: Екатерина добавил(-а) тег PRO; 2026-04-29 13:19:06: Екатерина добавил(-а) тег координатор; 2026-04-29 13:19:07: Екатерина добавил(-а) тег страт-п-с-26-09; 2026-04-29 15:15:49: Екатерина изменил(-а) название на 3.42. Техническая подготовка завершена | AB28: Лично сентябрь 2026 | AC28: =VLOOKUP(Y28,'впр данные'!A:B,2,1) -> координатор, страт-п-с-26-09 | AD28: =VLOOKUP(Y28,'впр данные'!A:C,3,1) -> координатор
... A110: 308 | B110: ЛИЧНО сентябрь 24.09.2026 | C110: Дивизион Конференции | D110: К работе | G110: Екатерина | H110: 2.06. Провести 40% глубинных интервью | I110: 01.06.2026 03:00 | J110: 04.06.2026 | L110: Действие | M110: Низкий | N110: N | P110: 28.04.2026 16:13:47 | S110: Екатерина | V110: N | W110: N | Y110: PRE, Продюсер, страт-п-с-26-09 | AA110: 2026-04-28 16:13:47: Екатерина создал(-а) задачу; 2026-04-28 17:14:48: Екатерина изменил(-а) название на 2.06. Провести 40% глубинных интервью; 2026-04-28 19:40:41: Екатерина добавил(-а) тег PRE; 2026-04-28 19:41:06: Екатерина добавил(-а) тег Продюсер; 2026-04-28 19:41:09: Екатерина добавил(-а) тег страт-п-с-26-09; 2026-04-28 19:46:16: Екатерина изменил(-а) дату на 04.06.2026 - 04.06.2026; 2026-04-28 19:46:16: Екатерина изменил(-а) дату на 01.06.2026 - 01.06.2026; 2026-04-28 19:46:32: Екатерина изменил(-а) дату на 01.06.2026 - 04.06.2026; 2026-04-28 19:46:34: Екатерина изменил(-а) дату на 04.06.2026 - 04.06.2026; 2026-04-28 19:46:52: Екатерина изменил(-а) дату на 01.06.2026 - 04.06.2026; 2026-04-28 19:46:54: Екатерина изменил(-а) дату на 04.06.2026 - 04.06.2026; 2026-04-28 19:47:08: Екатерина изменил(-а) дату на 01.06.2026 - 04.06.2026; 2026-04-29 10:35:45: Екатерина добавил(-а) подзадачу #307 2.05. Провести конкурентный анализ | AB110: Лично сентябрь 2026 | AC110: =VLOOKUP(Y110,'впр данные'!A:B,2,1) -> продюсер, страт-п-с-26-09 | AD110: =VLOOKUP(Y110,'впр данные'!A:C,3,1) -> продюсер
A111: 307 | B111: ЛИЧНО сентябрь 24.09.2026 | C111: Дивизион Конференции | D111: К работе | E111: 2.06. Провести 40% глубинных интервью | F111: 2.06. Провести 40% глубинных интервью | G111: Екатерина | H111: 2.05. Провести конкурентный анализ | I111: 01.06.2026 03:00 | J111: 04.06.2026 | L111: Действие | M111: Низкий | N111: N | P111: 28.04.2026 16:13:33 | S111: Екатерина | V111: N | W111: N | Y111: PRE, Продюсер, страт-п-с-26-09 | AA111: 2026-04-28 16:13:34: Екатерина создал(-а) задачу; 2026-04-28 17:14:26: Екатерина изменил(-а) название на 2.05. Провести конкурентный анализ; 2026-04-28 19:39:56: Екатерина добавил(-а) тег PRE; 2026-04-28 19:40:47: Екатерина добавил(-а) тег Продюсер; 2026-04-28 19:40:48: Екатерина добавил(-а) тег страт-п-с-26-09; 2026-04-28 19:46:09: Екатерина изменил(-а) дату на 01.06.2026 - 01.06.2026; 2026-04-28 19:46:09: Екатерина изменил(-а) дату на 04.06.2026 - 04.06.2026; 2026-04-28 19:46:25: Екатерина изменил(-а) дату на 01.06.2026 - 04.06.2026; 2026-04-29 10:35:45: Екатерина изменил(-а) родительскую задачу на #308 2.06. Провести 40% глубинных интервью | AB111: Лично сентябрь 2026 | AC111: =VLOOKUP(Y111,'впр данные'!A:B,2,1) -> продюсер, страт-п-с-26-09 | AD111: =VLOOKUP(Y111,'впр данные'!A:C,3,1) -> продюсер
A112: 306 | B112: ЛИЧНО сентябрь 24.09.2026 | C112: Дивизион Конференции | D112: К работе | G112: Екатерина | H112: 2.04. Провести кабинетное исследование | I112: 01.06.2026 03:00 | J112: 04.06.2026 | L112: Действие | M112: Низкий | N112: N | P112: 28.04.2026 16:13:25 | S112: Екатерина | V112: N | W112: N | Y112: PRE, Продюсер, страт-п-с-26-09 | AA112: 2026-04-28 16:13:25: Екатерина создал(-а) задачу; 2026-04-28 17:14:12: Екатерина изменил(-а) название на 2.04. Провести кабинетное исследование; 2026-04-28 19:39:53: Екатерина добавил(-а) тег PRE; 2026-04-28 19:40:25: Екатерина добавил(-а) тег Продюсер; 2026-04-28 19:40:26: Екатерина добавил(-а) тег страт-п-с-26-09; 2026-04-28 19:45:54: Екатерина изменил(-а) дату на 01.06.2026; 2026-04-28 19:45:54: Екатерина изменил(-а) дату на 04.06.2026; 2026-04-28 19:46:00: Екатерина изменил(-а) дату на 01.06.2026 - 04.06.2026 | AB112: Лично сентябрь 2026 | AC112: =VLOOKUP(Y112,'впр данные'!A:B,2,1) -> продюсер, страт-п-с-26-09 | AD112: =VLOOKUP(Y112,'впр данные'!A:C,3,1) -> продюсер
A113: 305 | B113: ЛИЧНО сентябрь 24.09.2026 | C113: Дивизион Конференции | D113: К работе | G113: Екатерина | H113: 2.03. Утвердить с ШП пакеты на возможность реализации на площадке | I113: 25.05.2026 03:00 | J113: 28.05.2026 | L113: Действие | M113: Низкий | N113: N | P113: 28.04.2026 16:12:56 | S113: Екатерина | V113: N | W113: N | Y113: PRE, Продюсер, страт-п-с-26-09 | AA113: 2026-04-28 16:12:58: Екатерина создал(-а) задачу; 2026-04-28 17:13:57: Екатерина изменил(-а) название на 2.03. Утвердить с ШП пакеты на возможность реализации на площадке; 2026-04-28 19:25:13: Екатерина добавил(-а) тег PRE; 2026-04-28 19:40:04: Екатерина добавил(-а) тег Продюсер; 2026-04-28 19:40:06: Екатерина добавил(-а) тег страт-п-с-26-09; 2026-04-28 19:45:35: Екатерина изменил(-а) дату на 25.05.2026; 2026-04-28 19:45:35: Екатерина изменил(-а) дату на 25.05.2026 - 25.05.2026; 2026-04-28 19:45:38: Екатерина изменил(-а) дату на 25.05.2026 - 28.05.2026 | AB113: Лично сентябрь 2026 | AC113: =VLOOKUP(Y113,'впр данные'!A:B,2,1) -> продюсер, страт-п-с-26-09 | AD113: =VLOOKUP(Y113,'впр данные'!A:C,3,1) -> продюсер
A114: 303 | B114: ЛИЧНО сентябрь 24.09.2026 | C114: Дивизион Конференции | D114: К работе | G114: Екатерина | H114: Страт-п-с-26-09 Финиш вехи Пост | I114: 28.09.2026 03:00 | J114: 01.10.2026 | L114: Действие | M114: Низкий | N114: N | P114: 28.04.2026 16:06:48 | R114: Елена | S114: Екатерина, Елена | V114: N | W114: N | Y114: страт-п-с-26-09, Операционный директор, финиш вехи Post | AA114: 2026-04-28 16:06:49: Екатерина создал(-а) задачу; 2026-04-28 16:07:27: Екатерина добавил(-а) тег страт-п-с-26-09; 2026-04-28 16:07:31: Екатерина добавил(-а) тег Операционный директор; 2026-04-28 16:07:47: Екатерина изменил(-а) дату на 28.09.2026; 2026-04-28 16:07:49: Екатерина изменил(-а) дату на 01.10.2026; 2026-04-28 16:07:53: Екатерина изменил(-а) дату на 28.09.2026 - 01.10.2026; 2026-04-28 16:08:28: Екатерина изменил(-а) название на Финиш вехи Пост; 2026-04-28 16:31:23: Екатерина добавил(-а) тег финиш вехи Post; 2026-04-28 16:35:26: Екатерина изменил(-а) название на СтратФиниш вехи Пост; 2026-04-28 16:35:31: Екатерина изменил(-а) название на Страт-пФиниш вехи Пост; 2026-04-28 16:35:34: Екатерина изменил(-а) название на Страт-п-сФиниш вехи Пост; 2026-04-28 16:35:40: Екатерина изменил(-а) название на Страт-п-с-26Финиш вехи Пост; 2026-04-28 16:35:44: Екатерина изменил(-а) название на Страт-п-с-26-09 Финиш вехи Пост; 2026-04-28 16:35:53: Екатерина изменил(-а) название на Лично Страт-п-с-26-09 Финиш вехи Пост; 2026-04-28 16:35:54: Екатерина изменил(-а) название на Лично сенСтрат-п-с-26-09 Финиш вехи Пост; 2026-04-28 16:35:57: Екатерина изменил(-а) название на Лично сентябрь 2026 Страт-п-с-26-09 Финиш вехи Пост; 2026-04-28 16:36:10: Екатерина изменил(-а) название на Страт-п-с-26-09 Финиш вехи Пост; 2026-04-30 10:51:34: Екатерина назначил(-а) Нелли исполнителем; 2026-04-30 10:51:44: Екатерина отстранил(-а) Нелли от задачи; 2026-04-30 10:52:03: Екатерина назначил(-а) Елена исполнителем | AB114: Лично сентябрь 2026 | AC114: =VLOOKUP(Y114,'впр данные'!A:B,2,1) -> страт-п-с-26-09, ШП, финиш вехи Post | AD114: =VLOOKUP(Y114,'впр данные'!A:C,3,1) -> Операцоинный директор
A115: 302 | B115: ЛИЧНО сентябрь 24.09.2026 | C115: Дивизион Конференции | D115: К работе | G115: Екатерина | H115: Страт-п-с-26-09 Старт вехи Pro | I115: 27.07.2026 03:00 | J115: 30.07.2026 | L115: Действие | M115: Низкий | N115: N | P115: 28.04.2026 15:53:36 | R115: Елена | S115: Екатерина, Елена | V115: N | W115: N | Y115: страт-п-с-26-09, Операционный директор, старт вехи Pro | AA115: 2026-04-28 15:53:36: Екатерина создал(-а) задачу; 2026-04-28 15:53:46: Екатерина добавил(-а) тег страт-п-с-26-09; 2026-04-28 15:53:49: Екатерина добавил(-а) тег Операционный директор; 2026-04-28 15:54:27: Екатерина изменил(-а) дату на 27.07.2026; 2026-04-28 15:54:32: Екатерина изменил(-а) дату на 27.07.2026 - 27.07.2026; 2026-04-28 15:54:36: Екатерина изменил(-а) дату на 27.07.2026 - 30.07.2026; 2026-04-28 15:54:48: Екатерина изменил(-а) название на 0Старт вехи Pro; 2026-04-28 15:54:50: Екатерина изменил(-а) название на 0.Старт вехи Pro; 2026-04-28 15:54:55: Екатерина изменил(-а) название на 0.2. Старт вехи Pro; 2026-04-28 15:54:56: Екатерина изменил(-а) название на 0.2.Старт вехи Pro; 2026-04-28 15:55:33: Екатерина изменил(-а) название на 0.2. Старт вехи Pro; 2026-04-28 16:08:16: Екатерина изменил(-а) название на Старт вехи Pro; 2026-04-28 16:30:32: Екатерина добавил(-а) тег старт вехи Pro; 2026-04-28 16:31:00: Екатерина добавил(-а) тег финиш вехи Post; 2026-04-28 16:31:17: Екатерина убрал(-а) тег финиш вехи Post; 2026-04-28 16:36:29: Екатерина изменил(-а) название на Страт-п-с-26-09Старт вехи Pro; 2026-04-28 16:36:30: Екатерина изменил(-а) название на Страт-п-с-26-09 Старт вехи Pro; 2026-04-30 10:52:02: Екатерина назначил(-а) Елена исполнителем | AB115: Лично сентябрь 2026 | AC115: =VLOOKUP(Y115,'впр данные'!A:B,2,1) -> страт-п-с-26-09, ШП, старт вехи Pro | AD115: =VLOOKUP(Y115,'впр данные'!A:C,3,1) -> Операцоинный директор
A116: 301 | B116: ЛИЧНО сентябрь 24.09.2026 | C116: Дивизион Конференции | D116: К работе | G116: Екатерина | H116: Страт-п-с-26-09 Старт вехи Pre | I116: 18.05.2026 03:00 | J116: 21.05.2026 | L116: Действие | M116: Низкий | N116: N | P116: 28.04.2026 15:47:42 | R116: Елена | S116: Екатерина, Елена | V116: N | W116: N | Y116: страт-п-с-26-09, Операционный директор, Старт вехи Pre | AA116: 2026-04-28 15:47:42: Екатерина создал(-а) задачу; 2026-04-28 15:47:57: Екатерина добавил(-а) тег страт-п-с-26-09; 2026-04-28 15:47:57: Екатерина добавил(-а) тег ШП; 2026-04-28 15:48:04: Екатерина убрал(-а) тег ШП; 2026-04-28 15:48:26: Екатерина добавил(-а) тег Операционный директор; 2026-04-28 15:49:18: Екатерина изменил(-а) дату на 18.05.2026; 2026-04-28 15:49:19: Екатерина изменил(-а) дату на 21.05.2026; 2026-04-28 15:49:20: Екатерина изменил(-а) дату на 18.05.2026; 2026-04-28 15:49:23: Екатерина изменил(-а) дату на 18.05.2026 - 18.05.2026; 2026-04-28 15:49:25: Екатерина изменил(-а) дату на 18.05.2026 - 21.05.2026; 2026-04-28 15:55:20: Екатерина изменил(-а) название на 0Старт вехи Pre; 2026-04-28 15:55:22: Екатерина изменил(-а) название на 0.1.Старт вехи Pre; 2026-04-28 15:55:25: Екатерина изменил(-а) название на 0.1. Старт вехи Pre; 2026-04-28 16:07:15: Екатерина изменил(-а) название на Старт вехи Pre; 2026-04-28 16:30:13: Екатерина добавил(-а) тег Старт вехи Pre; 2026-04-28 16:36:36: Екатерина изменил(-а) название на Страт-п-с-26-09Старт вехи Pre; 2026-04-28 16:36:36: Екатерина изменил(-а) название на Страт-п-с-26-09 Старт вехи Pre; 2026-04-30 10:51:58: Екатерина назначил(-а) Елена исполнителем | AB116: Лично сентябрь 2026 | AC116: =VLOOKUP(Y116,'впр данные'!A:B,2,1) -> страт-п-с-26-09, ШП, Старт вехи Pre | AD116: =VLOOKUP(Y116,'впр данные'!A:C,3,1) -> Операцоинный директор
A117: 300 | B117: ЛИЧНО сентябрь 24.09.2026 | E117: 2.01. Провести Презентацию проекта на Первичном совещании | F117: 2.01. Провести Презентацию проекта на Первичном совещании | G117: Екатерина | H117: 2.1.10. Произвести сверку наличия брони по площадке - сверяем с годовым планом по бронированию мест проведения | I117: 18.05.2026 03:00 | J117: 19.05.2026 | L117: Действие | M117: Низкий | N117: N | P117: 28.04.2026 15:43:55 | S117: Екатерина | V117: N | W117: N | AA117: 2026-04-28 15:43:55: Екатерина создал(-а) задачу; 2026-04-28 19:36:07: Екатерина изменил(-а) дату на 18.05.2026 - 18.05.2026; 2026-04-28 19:36:10: Екатерина изменил(-а) дату на 18.05.2026 - 19.05.2026; 2026-04-28 19:38:53: Екатерина добавил(-а) задачу в проект ЛИЧНО сентябрь 24.09.2026 | AB117: Лично сентябрь 2026 | AC117: =VLOOKUP(Y117,'впр данные'!A:B,2,1) -> #N/A | AD117: =VLOOKUP(Y117,'впр данные'!A:C,3,1) -> #N/A
A118: 299 | B118: ЛИЧНО сентябрь 24.09.2026 | E118: 2.01. Провести Презентацию проекта на Первичном совещании | F118: 2.01. Провести Презентацию проекта на Первичном совещании | G118: Екатерина | H118: 2.1.9. Просмотреть Маркетинговый отчет подготовленный лидгеном (включающий отчет по источникам и каналам и отчет по отказам), даны комментарии по подготовке списка каналов | I118: 18.05.2026 03:00 | J118: 19.05.2026 | L118: Действие | M118: Низкий | N118: N | P118: 28.04.2026 15:43:45 | S118: Екатерина | V118: N | W118: N | AA118: 2026-04-28 15:43:45: Екатерина создал(-а) задачу; 2026-04-28 19:35:55: Екатерина изменил(-а) дату на 18.05.2026; 2026-04-28 19:35:58: Екатерина изменил(-а) дату на 18.05.2026 - 18.05.2026; 2026-04-28 19:36:01: Екатерина изменил(-а) дату на 18.05.2026 - 19.05.2026; 2026-04-28 19:38:48: Екатерина добавил(-а) задачу в проект ЛИЧНО сентябрь 24.09.2026 | AB118: Лично сентябрь 2026 | AC118: =VLOOKUP(Y118,'впр данные'!A:B,2,1) -> #N/A | AD118: =VLOOKUP(Y118,'впр данные'!A:C,3,1) -> #N/A
A119: 298 | B119: ЛИЧНО сентябрь 24.09.2026 | E119: 2.01. Провести Презентацию проекта на Первичном совещании | F119: 2.01. Провести Презентацию проекта на Первичном совещании | G119: Екатерина | H119: 2.1.8. Проанализированы косяки предыдущего мероприятия | I119: 18.05.2026 03:00 | J119: 19.05.2026 | L119: Действие | M119: Низкий | N119: N | P119: 28.04.2026 15:43:34 | S119: Екатерина | V119: N | W119: N | AA119: 2026-04-28 15:43:34: Екатерина создал(-а) задачу; 2026-04-28 19:35:39: Екатерина изменил(-а) дату на 18.05.2026; 2026-04-28 19:35:43: Екатерина изменил(-а) дату на 18.05.2026 - 18.05.2026; 2026-04-28 19:35:46: Екатерина изменил(-а) дату на 18.05.2026 - 19.05.2026; 2026-04-28 19:38:44: Екатерина добавил(-а) задачу в проект ЛИЧНО сентябрь 24.09.2026 | AB119: Лично сентябрь 2026 | AC119: =VLOOKUP(Y119,'впр данные'!A:B,2,1) -> #N/A | AD119: =VLOOKUP(Y119,'впр данные'!A:C,3,1) -> #N/A
A120: 297 | B120: ЛИЧНО сентябрь 24.09.2026 | E120: 2.01. Провести Презентацию проекта на Первичном совещании | F120: 2.01. Провести Презентацию проекта на Первичном совещании | G120: Екатерина | H120: 2.1.7. Протокол совещания подписать с шеф-продюсером и положить в специальную папку, обозначенную именем проекта и годом проведения | I120: 18.05.2026 03:00 | J120: 19.05.2026 | L120: Действие | M120: Низкий | N120: N | P120: 28.04.2026 15:43:23 | S120: Екатерина | V120: N | W120: N | AA120: 2026-04-28 15:43:23: Екатерина создал(-а) задачу; 2026-04-28 19:33:52: Екатерина изменил(-а) дату на 18.05.2026; 2026-04-28 19:33:54: Екатерина изменил(-а) дату на 19.05.2026; 2026-04-28 19:33:56: Екатерина изменил(-а) дату на 18.05.2026 - 19.05.2026; 2026-04-28 19:38:40: Екатерина добавил(-а) задачу в проект ЛИЧНО сентябрь 24.09.2026 | AB120: Лично сентябрь 2026 | AC120: =VLOOKUP(Y120,'впр данные'!A:B,2,1) -> #N/A | AD120: =VLOOKUP(Y120,'впр данные'!A:C,3,1) -> #N/A
A121: 296 | B121: ЛИЧНО сентябрь 24.09.2026 | E121: 2.01. Провести Презентацию проекта на Первичном совещании | F121: 2.01. Провести Презентацию проекта на Первичном совещании | G121: Екатерина | H121: 2.1.6. Сформировать Протокол совещания, в котором подитожены все предыдущие пункты | I121: 18.05.2026 03:00 | J121: 19.05.2026 | L121: Действие | M121: Низкий | N121: N | P121: 28.04.2026 15:43:04 | S121: Екатерина | V121: N | W121: N | AA121: 2026-04-28 15:43:05: Екатерина создал(-а) задачу; 2026-04-28 19:33:27: Екатерина изменил(-а) дату на 18.05.2026; 2026-04-28 19:33:30: Екатерина изменил(-а) дату на 18.05.2026 - 18.05.2026; 2026-04-28 19:33:32: Екатерина изменил(-а) дату на 18.05.2026 - 19.05.2026; 2026-04-28 19:33:37: Екатерина изменил(-а) дату на 19.05.2026 - 19.05.2026; 2026-04-28 19:33:42: Екатерина изменил(-а) дату на 18.05.2026 - 19.05.2026; 2026-04-28 19:38:33: Екатерина добавил(-а) задачу в проект ЛИЧНО сентябрь 24.09.2026 | AB121: Лично сентябрь 2026 | AC121: =VLOOKUP(Y121,'впр данные'!A:B,2,1) -> #N/A | AD121: =VLOOKUP(Y121,'впр данные'!A:C,3,1) -> #N/A
...

Sheet впр данные
A1: теги | B1: роль и мероприятие | C1: роль
A2: D, координатор, страт-п-с-26-09 | B2: координатор, страт-п-с-26-09 | C2: координатор
A3: D, Лидген, страт-п-с-26-09 | B3: лидген, страт-п-с-26-09 | C3: лидген
A4: D, Продюсер, страт-п-с-26-09 | B4: продюсер, страт-п-с-26-09 | C4: продюсер
A5: D, ШП, страт-п-с-26-09 | B5: ШП, страт-п-с-26-09 | C5: ШП
A6: POST, координатор, страт-п-с-26-09 | B6: координатор, страт-п-с-26-09 | C6: координатор
A7: POST, Лидген, страт-п-с-26-09 | B7: лидген, страт-п-с-26-09 | C7: лидген
A8: POST, Продюсер, страт-п-с-26-09 | B8: продюсер, страт-п-с-26-09 | C8: продюсер
A9: POST, РГП, страт-п-с-26-09 | B9: РГП, страт-п-с-26-09 | C9: РГП
A10: POST, ШП, страт-п-с-26-09 | B10: ШП, страт-п-с-26-09 | C10: ШП
A11: PRE, координатор, страт-п-с-26-09 | B11: координатор, страт-п-с-26-09 | C11: координатор
A12: PRE, Лидген, страт-п-с-26-09 | B12: лидген, страт-п-с-26-09 | C12: лидген
... A24: страт-п-с-26-09, Операционный директор, финиш вехи Post | B24: страт-п-с-26-09, ШП, финиш вехи Post | C24: Операцоинный директор

Sheet прогрессбар заданий 
B1: недельный номер спринта | C1: 14 pre | D1: 13 pre | E1: 12 pre | F1: 11 pre | G1: 10 pre | H1: 9 pre | I1: 8 pro | J1: 7 pro | K1: 6 pro | L1: 5 pro | M1: 4 pro | N1: 3 pro | O1: 2 pro | P1: 1 pro | Q1: 0 D | R1: 1 post | T1: просроченность задач | U1: цвет светофора | V1: 18 - 22 мая | W1: 25-29 мая | X1: 1-5 июня | Y1: 8-12 июня | Z1: 15-19 июня | AA1: 22-26 июня | AB1: 27 июля - 31 июля | AC1: 3-7 августа | AD1: 10-14 августа | AE1: 17-21 августа | AF1: 24-28 августа | AG1: 31 августа - 4 сентября | AH1: 7-11 сентября | AI1: 14-18 сентября | AJ1: 21-25 сентября | AK1: 28 сентября - 2 октября | AM1: выполнение задач | AN1: цвет светофора | AO1: 18 - 22 мая | AP1: 25-29 мая | AQ1: 1-5 июня | AR1: 8-12 июня | AS1: 15-19 июня | AT1: 22-26 июня | AU1: 27 июля - 31 июля | AV1: 3-7 августа | AW1: 10-14 августа | AX1: 17-21 августа | AY1: 24-28 августа | AZ1: 31 августа - 4 сентября | BA1: 7-11 сентября | BB1: 14-18 сентября | BC1: 21-25 сентября | BD1: 28 сентября - 2 октября | BF1: просроченность задач | BG1: цвет светофора | BH1: 18 - 22 мая | BI1: 25-29 мая | BJ1: 1-5 июня | BK1: 8-12 июня | BL1: 15-19 июня | BM1: 22-26 июня | BN1: 27 июля - 31 июля | BO1: 3-7 августа | BP1: 10-14 августа | BQ1: 17-21 августа | BR1: 24-28 августа | BS1: 31 августа - 4 сентября | BT1: 7-11 сентября | BU1: 14-18 сентября | BV1: 21-25 сентября | BW1: 28 сентября - 2 октября | BY1: выполнение задач | BZ1: цвет светофора | CA1: 18 - 22 мая | CB1: 25-29 мая | CC1: 1-5 июня | CD1: 8-12 июня | CE1: 15-19 июня | CF1: 22-26 июня | CG1: 27 июля - 31 июля | CH1: 3-7 августа | CI1: 10-14 августа | CJ1: 17-21 августа | CK1: 24-28 августа | CL1: 31 августа - 4 сентября | CM1: 7-11 сентября | CN1: 14-18 сентября | CO1: 21-25 сентября | CP1: 28 сентября - 2 октября | CS1: отклонение по просрочке | CT1: цвет светофора просрочки задач | CV1: выполнение | CW1: цвет светофора по выполнению задач
C2: 18 - 22 мая | D2: 25-29 мая | E2: 1-5 июня | F2: 8-12 июня | G2: 15-19 июня | H2: 22-26 июня | I2: 27 июля - 31 июля | J2: 3-7 августа | K2: 10-14 августа | L2: 17-21 августа | M2: 24-28 августа | N2: 31 августа - 4 сентября | O2: 7-11 сентября | P2: 14-18 сентября | Q2: 21-25 сентября | R2: 28 сентября - 2 октября | T2: меньше 20% | U2: зеленый | V2: 0 | W2: 0 | X2: 0 | Y2: 0 | Z2: 0 | AA2: 0 | AB2: 0 | AC2: 0 | AD2: 0 | AE2: 0 | AF2: 0 | AG2: 0 | AH2: 0 | AI2: 0 | AJ2: 0 | AK2: 0 | AM2: меньше 60% | AN2: красный | AO2: 0 | AP2: 0 | AQ2: 0 | AR2: 0 | AS2: 0 | AT2: 0 | AU2: 0 | AV2: 0 | AW2: 0 | AX2: 0 | AY2: 0 | AZ2: 0 | BA2: 0 | BB2: 0 | BC2: 0 | BD2: 0 | BF2: ШП, страт-п-с-26-09 | BG2: зеленый | BH2: 0 | BI2: 0 | BJ2: 0 | BK2: 0 | BL2: 0 | BM2: 0 | BN2: 0 | BO2: 0 | BP2: 0 | BQ2: 0 | BR2: 0 | BS2: 0 | BT2: 0 | BU2: 0 | BV2: 0 | BW2: 0 | BY2: ШП, страт-п-с-26-09 | BZ2: красный | CA2: 0 | CB2: 0 | CC2: 0 | CD2: 0 | CE2: 0 | CF2: 0 | CG2: 0 | CH2: 0 | CI2: 0 | CJ2: 0 | CK2: 0 | CL2: 0 | CM2: 0 | CN2: 0 | CO2: 0 | CP2: 0 | CS2: 0 | CT2: зеленый | CV2: 0 | CW2: красный
A3: 1 | B3: ШП, страт-п-с-26-09 | C3: 2 | D3: 3 | E3: 5 | F3: 5 | G3: 8 | H3: 8 | I3: 10 | J3: 11 | K3: 13 | L3: 14 | M3: 16 | N3: 17 | O3: 22 | P3: 27 | Q3: 29 | R3: 35 | T3: 20-40% | U3: желтый | V3: =C8/100*20 -> 1.2 | W3: =D8/100*20 -> 2.8 | X3: =E8/100*20 -> 6 | Y3: =F8/100*20 -> 7.6 | Z3: =G8/100*20 -> 9.2 | AA3: =H8/100*20 -> 10.8 | AB3: =I8/100*20 -> 13 | AC3: =J8/100*20 -> 15.4 | ... AK3: =R8/100*20 -> 43.8 | AM3: (60-80%) | AN3: желтый | AO3: 3.6 | AP3: 8.4 | AQ3: 18 | AR3: 22.8 | AS3: 27.6 | AT3: 32.4 | AU3: 39 | AV3: 46.2 | AW3: 54 | AX3: 61.8 | AY3: 71.4 | AZ3: 81 | BA3: 96 | BB3: 111.6 | BC3: 117 | BD3: 131.4 | BF3: продюсер, страт-п-с-26-09 | BG3: зеленый | BH3: 0 | BI3: 0 | BJ3: 0 | BK3: 0 | BL3: 0 | BM3: 0 | BN3: 0 | BO3: 0 | BP3: 0 | BQ3: 0 | BR3: 0 | BS3: 0 | BT3: 0 | BU3: 0 | BV3: 0 | BW3: 0 | BY3: продюсер, страт-п-с-26-09 | BZ3: красный | CA3: 0 | CB3: 0 | CC3: 0 | CD3: 0 | CE3: 0 | CF3: 0 | CG3: 0 | CH3: 0 | CI3: 0 | CJ3: 0 | CK3: 0 | CL3: 0 | CM3: 0 | CN3: 0 | CO3: 0 | CP3: 0 | CS3: 0.2 | CT3: желтый | CV3: 0.601 | CW3: желтый
